2025-08-29 13:51:26 | [31mERROR[0m | TMS_MAIN | error:82 | Validation error | Exception: File validation failed. Issues: ['file_path']
Traceback (most recent call last):
  File "C:\Users\Quincy Nguyen\Desktop\Automation Projects\BVC_Automator\tms_processor.py", line 149, in clean_and_process_data
    raise ValueError(f"File validation failed. Issues: {failed_steps}")
ValueError: File validation failed. Issues: ['file_path']
2025-08-29 13:51:26 | [31mERROR[0m | TMS_MAIN | error:82 | Validation error | Exception: File validation failed. Issues: ['file_path']
Traceback (most recent call last):
  File "C:\Users\Quincy Nguyen\Desktop\Automation Projects\BVC_Automator\tms_processor.py", line 149, in clean_and_process_data
    raise ValueError(f"File validation failed. Issues: {failed_steps}")
ValueError: File validation failed. Issues: ['file_path']
2025-08-29 13:51:26 | [31mERROR[0m | TMS_MAIN | error:82 | Validation error | Exception: File validation failed. Issues: ['file_path']
Traceback (most recent call last):
  File "C:\Users\Quincy Nguyen\Desktop\Automation Projects\BVC_Automator\tms_processor.py", line 149, in clean_and_process_data
    raise ValueError(f"File validation failed. Issues: {failed_steps}")
ValueError: File validation failed. Issues: ['file_path']
2025-08-29 13:51:26 | [31mERROR[0m | TMS_MAIN | error:82 | Validation error | Exception: File validation failed. Issues: ['file_path']
Traceback (most recent call last):
  File "C:\Users\Quincy Nguyen\Desktop\Automation Projects\BVC_Automator\tms_processor.py", line 149, in clean_and_process_data
    raise ValueError(f"File validation failed. Issues: {failed_steps}")
ValueError: File validation failed. Issues: ['file_path']
2025-08-29 13:51:26 | [31mERROR[0m | TMS_MAIN | error:82 | Validation error | Exception: File validation failed. Issues: ['file_path']
Traceback (most recent call last):
  File "C:\Users\Quincy Nguyen\Desktop\Automation Projects\BVC_Automator\tms_processor.py", line 149, in clean_and_process_data
    raise ValueError(f"File validation failed. Issues: {failed_steps}")
ValueError: File validation failed. Issues: ['file_path']
2025-08-29 13:51:26 | [31mERROR[0m | TMS_MAIN | error:82 | Validation error | Exception: File validation failed. Issues: ['file_path']
Traceback (most recent call last):
  File "C:\Users\Quincy Nguyen\Desktop\Automation Projects\BVC_Automator\tms_processor.py", line 149, in clean_and_process_data
    raise ValueError(f"File validation failed. Issues: {failed_steps}")
ValueError: File validation failed. Issues: ['file_path']
2025-08-29 13:51:26 | [31mERROR[0m | TMS_MAIN | error:82 | Validation error | Exception: File validation failed. Issues: ['file_path']
Traceback (most recent call last):
  File "C:\Users\Quincy Nguyen\Desktop\Automation Projects\BVC_Automator\tms_processor.py", line 149, in clean_and_process_data
    raise ValueError(f"File validation failed. Issues: {failed_steps}")
ValueError: File validation failed. Issues: ['file_path']
2025-08-29 13:51:51 | [31mERROR[0m | TMS_MAIN | error:82 | Validation error | Exception: File validation failed. Issues: ['file_path']
Traceback (most recent call last):
  File "C:\Users\Quincy Nguyen\Desktop\Automation Projects\BVC_Automator\tms_processor.py", line 149, in clean_and_process_data
    raise ValueError(f"File validation failed. Issues: {failed_steps}")
ValueError: File validation failed. Issues: ['file_path']
2025-08-29 13:51:51 | [31mERROR[0m | TMS_MAIN | error:82 | Validation error | Exception: File validation failed. Issues: ['excel_structure']
Traceback (most recent call last):
  File "C:\Users\Quincy Nguyen\Desktop\Automation Projects\BVC_Automator\tms_processor.py", line 149, in clean_and_process_data
    raise ValueError(f"File validation failed. Issues: {failed_steps}")
ValueError: File validation failed. Issues: ['excel_structure']
2025-08-29 13:52:09 | [31mERROR[0m | TMS_MAIN | error:82 | Validation error | Exception: File validation failed. Issues: ['file_path']
Traceback (most recent call last):
  File "C:\Users\Quincy Nguyen\Desktop\Automation Projects\BVC_Automator\tms_processor.py", line 149, in clean_and_process_data
    raise ValueError(f"File validation failed. Issues: {failed_steps}")
ValueError: File validation failed. Issues: ['file_path']
2025-08-29 13:52:09 | [31mERROR[0m | TMS_MAIN | error:82 | Validation error | Exception: File validation failed. Issues: ['excel_structure']
Traceback (most recent call last):
  File "C:\Users\Quincy Nguyen\Desktop\Automation Projects\BVC_Automator\tms_processor.py", line 149, in clean_and_process_data
    raise ValueError(f"File validation failed. Issues: {failed_steps}")
ValueError: File validation failed. Issues: ['excel_structure']
2025-08-29 14:03:18 | [31mERROR[0m | TMS_MAIN | error:82 | Validation error | Exception: File validation failed. Issues: ['file_path']
Traceback (most recent call last):
  File "C:\Users\Quincy Nguyen\Desktop\Automation Projects\BVC_Automator\tms_processor.py", line 149, in clean_and_process_data
    raise ValueError(f"File validation failed. Issues: {failed_steps}")
ValueError: File validation failed. Issues: ['file_path']
2025-08-29 14:03:18 | [31mERROR[0m | TMS_MAIN | error:82 | Validation error | Exception: File validation failed. Issues: ['excel_structure']
Traceback (most recent call last):
  File "C:\Users\Quincy Nguyen\Desktop\Automation Projects\BVC_Automator\tms_processor.py", line 149, in clean_and_process_data
    raise ValueError(f"File validation failed. Issues: {failed_steps}")
ValueError: File validation failed. Issues: ['excel_structure']
2025-08-29 14:04:18 | [31mERROR[0m | TMS_MAIN | error:82 | Unexpected processing error | file_path: C:/Users/Quincy Nguyen/Documents/Weekly Reports/August 2025/08.04 - 08.08 Reports/FERROWORKS BVC 08.04.25 - 08.08.25.xlsx | Exception: positional indexers are out-of-bounds
Traceback (most recent call last):
  File "C:\Users\Quincy Nguyen\Desktop\Automation Projects\BVC_Automator\tms_processor.py", line 205, in clean_and_process_data
    data_df = data_df.iloc[:, relevant_columns]
              ~~~~~~~~~~~~^^^^^^^^^^^^^^^^^^^^^
  File "C:\Users\Quincy Nguyen\AppData\Local\Programs\Python\Python313\Lib\site-packages\pandas\core\indexing.py", line 1184, in __getitem__
    return self._getitem_tuple(key)
           ~~~~~~~~~~~~~~~~~~~^^^^^
  File "C:\Users\Quincy Nguyen\AppData\Local\Programs\Python\Python313\Lib\site-packages\pandas\core\indexing.py", line 1690, in _getitem_tuple
    tup = self._validate_tuple_indexer(tup)
  File "C:\Users\Quincy Nguyen\AppData\Local\Programs\Python\Python313\Lib\site-packages\pandas\core\indexing.py", line 966, in _validate_tuple_indexer
    self._validate_key(k, i)
    ~~~~~~~~~~~~~~~~~~^^^^^^
  File "C:\Users\Quincy Nguyen\AppData\Local\Programs\Python\Python313\Lib\site-packages\pandas\core\indexing.py", line 1612, in _validate_key
    raise IndexError("positional indexers are out-of-bounds")
IndexError: positional indexers are out-of-bounds
2025-08-29 14:08:37 | [31mERROR[0m | TMS_MAIN | error:82 | Validation error | Exception: File validation failed. Issues: ['file_path']
Traceback (most recent call last):
  File "C:\Users\Quincy Nguyen\Desktop\Automation Projects\BVC_Automator\tms_processor.py", line 149, in clean_and_process_data
    raise ValueError(f"File validation failed. Issues: {failed_steps}")
ValueError: File validation failed. Issues: ['file_path']
2025-08-29 14:08:37 | [31mERROR[0m | TMS_MAIN | error:82 | Validation error | Exception: File validation failed. Issues: ['excel_structure']
Traceback (most recent call last):
  File "C:\Users\Quincy Nguyen\Desktop\Automation Projects\BVC_Automator\tms_processor.py", line 149, in clean_and_process_data
    raise ValueError(f"File validation failed. Issues: {failed_steps}")
ValueError: File validation failed. Issues: ['excel_structure']
